Workbook

Sheet Start Here
B1: MarginKite Seller Profit Tracker
B2: Fees last checked: 2026-10-21 | US sellers | Etsy + Shopify
B5: What it does
C6: Shows what you really keep from each Etsy or Shopify sale after every fee, product cost and shipping. Compares Etsy and Shopify side by side, tells you the price to charge for a target margin, shows when a Shopify plan pays for itself, and tracks orders, refunds and overhead month by month.
B8: Open it
B9: Google Sheets | C9: Upload the .xlsx to Google Drive, open it, then File > Save as Google Sheets. Work in that Google Sheets copy.
B10: Excel | C10: Open the .xlsx in Excel 2016 or newer (Windows or Mac). If you see 'Enable Editing', click it.
B12: 5 steps to your first result
B13: Step 1 | C13: Settings: enter your hourly rate, answer the Etsy $10k question, and pick your Shopify plan, billing and payment provider.
B14: Step 2 | C14: Products: type each product with materials, packaging and labour minutes. Unit cost is worked out for you.
B15: Step 3 | C15: Price Calculator: pick a product and enter price, shipping charged and shipping cost. Read Etsy vs Shopify profit, the price for your target margin, and when Shopify pays off.
B16: Step 4 | C16: Orders Log: add one row per order (yellow columns A-L). Fees and profit fill in automatically.
B17: Step 5 | C17: Expenses, then Dashboard: add monthly overhead, set the first month on the Dashboard, and read your monthly profit.
B19: Colour key
B20: Yellow cell | C20: You type here (inputs).
B21: Blue cell | C21: Calculated for you and locked, so it can't be overwritten by accident.
B22: Unlocking | C22: Sheets are protected with NO password. Excel: Review > Unprotect Sheet. Google Sheets: Data > Protect sheets and ranges, then remove the protection. Edit formulas at your own risk.
B24: Delete the sample data
C25: The file ships with 5 sample products, 30 sample orders (Aug-Oct 2026) and 3 months of expenses so you can see it working. To start fresh, select these yellow ranges and press Delete (clear the contents; don't delete rows):
B26: Orders Log | C26: A6:L505
B27: Expenses | C27: A6:F65
B28: Products | C28: A5:D54 (after the orders, so nothing points at a missing product)
B29: Dashboard | C29: Set 'First month to show' (C4) to your first month.
B30: Price Calculator | C30: Pick one of your own products in C4.
B32: Good to know
B33: Sales tax | C33: Etsy collects US sales tax for you. It isn't your revenue, so leave it out of every amount.
B34: Refunds | C34: Mark Refunded = Y. Leave 'Partial refund $' blank for a full refund. 'Etsy fees credited back?' = Y credits Etsy's % fees in proportion to the refund (see the RULE rows on Settings).
B35: Offsite Ads | C35: Set Y only on orders Etsy says came from an Offsite Ad. The 15%/12% rate and the $100 cap come from Settings.
B36: Fee changes | C36: Every rate lives in the Settings fee table with its date, source and status. Update a value there and the whole workbook follows. Rows marked UNVERIFIED or ASSUMPTION are best estimates.
B38: Disclaimer
C39: All figures are estimates. Fees as of 2026-10-21; Etsy fees are not yet verified against Etsy's own fee page. Check your own Etsy and Shopify statements. This is not tax or accounting advice.
B41: Made with AI
C42: MarginKite is a small shop. AI helped design and build this template; every formula was checked against hand-worked examples before release.

Sheet Settings
A1: Settings
A2: Fees as of 2026-10-21. Estimates only - check your own Etsy and Shopify statements.
A4: YOUR SETTINGS
B5: Your hourly rate for labour ($/hour) | C5: 18 | D5: Used on the Products tab to cost your time.
B6: Etsy sales in the last 12 months $10,000 or more? (Y/N) | C6: N | D6: Sets the Offsite Ads rate: N = 15%, Y = 12%.
B7: Shopify plan | C7: Basic | D7: Basic, Grow, Advanced or Plus.
B8: Shopify billing | C8: Monthly | D8: Monthly or Yearly (yearly is cheaper per month).
B9: Payment provider on Shopify | C9: Shopify Payments | D9: Third-party adds Shopify's extra fee on top of your provider's fee.
A11: CALCULATED FROM YOUR SETTINGS
B12: Etsy Offsite Ads rate in use | C12: =IF($C$6="Y",$C$24,$C$23)
B13: Shopify plan cost per month (plan + billing) | C13: =INDEX($C$19:$C$60,MATCH("Shopify|"&$C$7&"|"&$C$8,$A$19:$A$60,0))
B14: Shopify % fee per order in use | C14: =IF($C$9="Shopify Payments",INDEX($C$19:$C$60,MATCH("Shopify|"&$C$7&"|"&"Card %",$A$19:$A$60,0)),$C$52+INDEX($C$19:$C$60,MATCH("Shopify|"&$C$7&"|"&"Third-party %",$A$19:$A$60,0)))
B15: Shopify fixed fee per order in use | C15: =IF($C$9="Shopify Payments",INDEX($C$19:$C$60,MATCH("Shopify|"&$C$7&"|"&"Card fixed",$A$19:$A$60,0)),$C$53)
A17: FEE TABLE - every rate the workbook uses. Edit Value / As of / Source / Status when fees change.
A18: Key (don't edit) | B18: Fee | C18: Value | D18: Unit | E18: As of | F18: Source | G18: Status | H18: Used in formulas? | I18: Notes
A19: ETSY_LISTING | B19: Etsy listing fee | C19: 0.2 | D19: $ per unit sold | E19: 46316 | F19: https://checkoutpage.com/blog/etsy-fees ; https://www.listadum.com/etsy-fee-calculator | G19: UNVERIFIED | H19: Yes | I19: Renews when an item sells, again for each extra unit. ASSUMPTION (conservative): $0.20 x quantity on every Etsy order. Official page to check: https://www.etsy.com/legal/fees/
A20: ETSY_TXN | B20: Etsy transaction fee | C20: 0.065 | D20: of item price + shipping | E20: 46316 | F20: https://checkoutpage.com/blog/etsy-fees ; https://craftybase.com/etsy-fee-calculator | G20: UNVERIFIED | H20: Yes | I20: Charged on item price plus shipping (and gift wrap). Official page to check: https://www.etsy.com/legal/fees/
A21: ETSY_PROC_PCT | B21: Etsy payment processing (US) - percent | C21: 0.03 | D21: of order total | E21: 46316 | F21: https://checkoutpage.com/blog/etsy-fees ; https://craftybase.com/etsy-fee-calculator | G21: UNVERIFIED | H21: Yes | I21: Charged on the order total, including sales tax (see the sales tax rate below).
A22: ETSY_PROC_FIXED | B22: Etsy payment processing (US) - fixed | C22: 0.25 | D22: $ per order | E22: 46316 | F22: https://checkoutpage.com/blog/etsy-fees ; https://craftybase.com/etsy-fee-calculator | G22: UNVERIFIED | H22: Yes
A23: ETSY_OFFSITE_15 | B23: Etsy Offsite Ads - shop under $10k / 12 months | C23: 0.15 | D23: of attributed order | E23: 46316 | F23: https://checkoutpage.com/blog/etsy-fees ; https://blog.marmalead.com/etsy-vs-shopify/ | G23: UNVERIFIED | H23: Yes | I23: Used when you answer N to the $10k question above. Opt-out allowed.
A24: ETSY_OFFSITE_12 | B24: Etsy Offsite Ads - shop at $10k+ / 12 months | C24: 0.12 | D24: of attributed order | E24: 46316 | F24: https://checkoutpage.com/blog/etsy-fees ; https://blog.marmalead.com/etsy-vs-shopify/ | G24: UNVERIFIED | H24: Yes | I24: Used when you answer Y to the $10k question above. Mandatory at this level.
A25: ETSY_OFFSITE_CAP | B25: Etsy Offsite Ads - cap per order | C25: 100 | D25: $ max per order | E25: 46316 | F25: https://checkoutpage.com/blog/etsy-fees ; https://blog.marmalead.com/etsy-vs-shopify/ | G25: UNVERIFIED | H25: Yes
A26: ETSY_OFFSITE_THRESHOLD | B26: Etsy Offsite Ads - sales threshold | C26: 10000 | D26: $ in last 12 months | E26: 46316 | F26: https://checkoutpage.com/blog/etsy-fees ; https://blog.marmalead.com/etsy-vs-shopify/ | G26: UNVERIFIED | H26: Info | I26: For reference: you answer the Y/N question above.
A27: ETSY_REG_FEE | B27: Etsy Regulatory Operating Fee (US) | C27: 0 | D27: none for US sellers | E27: 46316 | F27: https://checkoutpage.com/blog/etsy-fees ; https://craftybase.com/etsy-fee-calculator | G27: UNVERIFIED | H27: No | I27: Applies only in some other countries (e.g. UK). Not modeled in v1 (US only).
A28: ETSY_CURRENCY | B28: Etsy currency conversion | C28: 0.025 | D28: only if currencies differ | E28: 46316 | F28: Prior knowledge, not checked this session | G28: UNVERIFIED | H28: No | I28: Not modeled: US sellers listing in USD with a USD account don't pay it.
A29: ETSY_PLUS | B29: Etsy Plus subscription (optional) | C29: 10 | D29: $ per month | E29: 46316 | F29: Prior knowledge, not checked this session | G29: UNVERIFIED | H29: No | I29: If you subscribe, add it on the Expenses tab.
A30: ETSY_ADS | B30: Etsy Ads (onsite) | C30: Your spend | D30: daily budget you set | E30: 46316 | F30: https://www.listadum.com/etsy-fee-calculator | G30: UNVERIFIED | H30: Expenses tab | I30: Enter your monthly spend on the Expenses tab.
A31: ETSY_SHARE_SAVE | B31: Etsy Share & Save credit | C31: Not modeled | D31: rate not confirmed | E31: 46316 | F31: Competitor listing snippet | G31: UNVERIFIED | H31: No | I31: A credit to you; leaving it out understates profit slightly.
A32: Shopify|Basic|Monthly | B32: Shopify Basic plan - billed monthly | C32: 27 | D32: $ per month | E32: 46316 | F32: https://www.shopify.com/pricing | G32: VERIFIED | H32: Yes
A33: Shopify|Basic|Yearly | B33: Shopify Basic plan - billed yearly | C33: 19 | D33: $ per month | E33: 46316 | F33: https://www.shopify.com/pricing | G33: VERIFIED | H33: Yes
A34: Shopify|Basic|Card % | B34: Shopify Payments online card rate - Basic | C34: 0.029 | D34: of order total | E34: 46316 | F34: https://www.shopify.com/pricing (search index) ; https://qualimero.com/en/blog/shopify-transaction-fees | G34: UNVERIFIED | H34: Yes | I34: Check Settings > Payments in your Shopify admin.
A35: Shopify|Basic|Card fixed | B35: Shopify Payments fixed fee - Basic | C35: 0.3 | D35: $ per order | E35: 46316 | F35: https://www.shopify.com/pricing (search index) ; https://qualimero.com/en/blog/shopify-transaction-fees | G35: UNVERIFIED | H35: Yes
A36: Shopify|Basic|Third-party % | B36: Shopify fee if NOT using Shopify Payments - Basic | C36: 0.02 | D36: of order total | E36: 46316 | F36: https://www.shopify.com/pricing | G36: VERIFIED | H36: Yes | I36: Charged by Shopify on top of your provider's own fee.
A37: Shopify|Grow|Monthly | B37: Shopify Grow plan - billed monthly | C37: 72 | D37: $ per month | E37: 46316 | F37: https://www.shopify.com/pricing | G37: VERIFIED | H37: Yes
A38: Shopify|Grow|Yearly | B38: Shopify Grow plan - billed yearly | C38: 54 | D38: $ per month | E38: 46316 | F38: https://www.shopify.com/pricing | G38: VERIFIED | H38: Yes
A39: Shopify|Grow|Card % | B39: Shopify Payments online card rate - Grow | C39: 0.027 | D39: of order total | E39: 46316 | F39: https://www.shopify.com/pricing (search index) ; https://qualimero.com/en/blog/shopify-transaction-fees | G39: UNVERIFIED | H39: Yes | I39: Check Settings > Payments in your Shopify admin. Some sources say 2.6%; higher figure used (conservative).
A40: Shopify|Grow|Card fixed | B40: Shopify Payments fixed fee - Grow | C40: 0.3 | D40: $ per order | E40: 46316 | F40: https://www.shopify.com/pricing (search index) ; https://qualimero.com/en/blog/shopify-transaction-fees | G40: UNVERIFIED | H40: Yes
A41: Shopify|Grow|Third-party % | B41: Shopify fee if NOT using Shopify Payments - Grow | C41: 0.01 | D41: of order total | E41: 46316 | F41: https://www.shopify.com/pricing | G41: VERIFIED | H41: Yes | I41: Charged by Shopify on top of your provider's own fee.
A42: Shopify|Advanced|Monthly | B42: Shopify Advanced plan - billed monthly | C42: 399 | D42: $ per month | E42: 46316 | F42: https://www.shopify.com/pricing | G42: VERIFIED | H42: Yes
A43: Shopify|Advanced|Yearly | B43: Shopify Advanced plan - billed yearly | C43: 299 | D43: $ per month | E43: 46316 | F43: https://www.shopify.com/pricing | G43: VERIFIED | H43: Yes
...

Sheet Products
A1: Products
A2: One row per product. Yellow = you type. Blue = calculated. Unit cost feeds every profit figure.
A4: Product name | B4: Materials ($/unit) | C4: Packaging ($/unit) | D4: Labour (minutes/unit) | E4: Labour cost ($/unit) | F4: Total unit cost | G4: Units sold (Orders Log) | H4: Net profit (Orders Log) | I4: Rank helper | K4: Notes
A5: Ceramic Mug | B5: 6.5 | C5: 1.2 | D5: 25 | E5: =IF($A5="","",$D5/60*Settings!$C$5) | F5: =IF($A5="","",$B5+$C5+$E5) | G5: =IF($A5="","",SUMIFS('Orders Log'!$D$6:$D$505,'Orders Log'!$C$6:$C$505,$A5)) | H5: =IF($A5="","",SUMIFS('Orders Log'!$V$6:$V$505,'Orders Log'!$C$6:$C$505,$A5)) | I5: =IF($A5="","",$H5-ROW()/1000000000) | K5: Labour cost = minutes / 60 x your hourly rate (Settings).
A6: Linen Tote Bag | B6: 5 | C6: 0.8 | D6: 20 | E6: =IF($A6="","",$D6/60*Settings!$C$5) | F6: =IF($A6="","",$B6+$C6+$E6) | G6: =IF($A6="","",SUMIFS('Orders Log'!$D$6:$D$505,'Orders Log'!$C$6:$C$505,$A6)) | H6: =IF($A6="","",SUMIFS('Orders Log'!$V$6:$V$505,'Orders Log'!$C$6:$C$505,$A6)) | I6: =IF($A6="","",$H6-ROW()/1000000000) | K6: Rank helper breaks ties for the Dashboard top/bottom lists. Ignore it.
A7: Soy Candle 8oz | B7: 3.4 | C7: 1 | D7: 15 | E7: =IF($A7="","",$D7/60*Settings!$C$5) | F7: =IF($A7="","",$B7+$C7+$E7) | G7: =IF($A7="","",SUMIFS('Orders Log'!$D$6:$D$505,'Orders Log'!$C$6:$C$505,$A7)) | H7: =IF($A7="","",SUMIFS('Orders Log'!$V$6:$V$505,'Orders Log'!$C$6:$C$505,$A7)) | I7: =IF($A7="","",$H7-ROW()/1000000000) | K7: Product names must be unique; the Orders Log looks them up by name.
A8: Beaded Bracelet | B8: 2.1 | C8: 0.6 | D8: 30 | E8: =IF($A8="","",$D8/60*Settings!$C$5) | F8: =IF($A8="","",$B8+$C8+$E8) | G8: =IF($A8="","",SUMIFS('Orders Log'!$D$6:$D$505,'Orders Log'!$C$6:$C$505,$A8)) | H8: =IF($A8="","",SUMIFS('Orders Log'!$V$6:$V$505,'Orders Log'!$C$6:$C$505,$A8)) | I8: =IF($A8="","",$H8-ROW()/1000000000)
A9: Art Print A4 | B9: 1.5 | C9: 0.9 | D9: 5 | E9: =IF($A9="","",$D9/60*Settings!$C$5) | F9: =IF($A9="","",$B9+$C9+$E9) | G9: =IF($A9="","",SUMIFS('Orders Log'!$D$6:$D$505,'Orders Log'!$C$6:$C$505,$A9)) | H9: =IF($A9="","",SUMIFS('Orders Log'!$V$6:$V$505,'Orders Log'!$C$6:$C$505,$A9)) | I9: =IF($A9="","",$H9-ROW()/1000000000)
E10: =IF($A10="","",$D10/60*Settings!$C$5) | F10: =IF($A10="","",$B10+$C10+$E10) | G10: =IF($A10="","",SUMIFS('Orders Log'!$D$6:$D$505,'Orders Log'!$C$6:$C$505,$A10)) | H10: =IF($A10="","",SUMIFS('Orders Log'!$V$6:$V$505,'Orders Log'!$C$6:$C$505,$A10)) | I10: =IF($A10="","",$H10-ROW()/1000000000)
E11: =IF($A11="","",$D11/60*Settings!$C$5) | F11: =IF($A11="","",$B11+$C11+$E11) | G11: =IF($A11="","",SUMIFS('Orders Log'!$D$6:$D$505,'Orders Log'!$C$6:$C$505,$A11)) | H11: =IF($A11="","",SUMIFS('Orders Log'!$V$6:$V$505,'Orders Log'!$C$6:$C$505,$A11)) | I11: =IF($A11="","",$H11-ROW()/1000000000)
E12: =IF($A12="","",$D12/60*Settings!$C$5) | F12: =IF($A12="","",$B12+$C12+$E12) | G12: =IF($A12="","",SUMIFS('Orders Log'!$D$6:$D$505,'Orders Log'!$C$6:$C$505,$A12)) | H12: =IF($A12="","",SUMIFS('Orders Log'!$V$6:$V$505,'Orders Log'!$C$6:$C$505,$A12)) | I12: =IF($A12="","",$H12-ROW()/1000000000)
E13: =IF($A13="","",$D13/60*Settings!$C$5) | F13: =IF($A13="","",$B13+$C13+$E13) | G13: =IF($A13="","",SUMIFS('Orders Log'!$D$6:$D$505,'Orders Log'!$C$6:$C$505,$A13)) | H13: =IF($A13="","",SUMIFS('Orders Log'!$V$6:$V$505,'Orders Log'!$C$6:$C$505,$A13)) | I13: =IF($A13="","",$H13-ROW()/1000000000)
E14: =IF($A14="","",$D14/60*Settings!$C$5) | F14: =IF($A14="","",$B14+$C14+$E14) | G14: =IF($A14="","",SUMIFS('Orders Log'!$D$6:$D$505,'Orders Log'!$C$6:$C$505,$A14)) | H14: =IF($A14="","",SUMIFS('Orders Log'!$V$6:$V$505,'Orders Log'!$C$6:$C$505,$A14)) | I14: =IF($A14="","",$H14-ROW()/1000000000)
E15: =IF($A15="","",$D15/60*Settings!$C$5) | F15: =IF($A15="","",$B15+$C15+$E15) | G15: =IF($A15="","",SUMIFS('Orders Log'!$D$6:$D$505,'Orders Log'!$C$6:$C$505,$A15)) | H15: =IF($A15="","",SUMIFS('Orders Log'!$V$6:$V$505,'Orders Log'!$C$6:$C$505,$A15)) | I15: =IF($A15="","",$H15-ROW()/1000000000)
E16: =IF($A16="","",$D16/60*Settings!$C$5) | F16: =IF($A16="","",$B16+$C16+$E16) | G16: =IF($A16="","",SUMIFS('Orders Log'!$D$6:$D$505,'Orders Log'!$C$6:$C$505,$A16)) | H16: =IF($A16="","",SUMIFS('Orders Log'!$V$6:$V$505,'Orders Log'!$C$6:$C$505,$A16)) | I16: =IF($A16="","",$H16-ROW()/1000000000)
E17: =IF($A17="","",$D17/60*Settings!$C$5) | F17: =IF($A17="","",$B17+$C17+$E17) | G17: =IF($A17="","",SUMIFS('Orders Log'!$D$6:$D$505,'Orders Log'!$C$6:$C$505,$A17)) | H17: =IF($A17="","",SUMIFS('Orders Log'!$V$6:$V$505,'Orders Log'!$C$6:$C$505,$A17)) | I17: =IF($A17="","",$H17-ROW()/1000000000)
E18: =IF($A18="","",$D18/60*Settings!$C$5) | F18: =IF($A18="","",$B18+$C18+$E18) | G18: =IF($A18="","",SUMIFS('Orders Log'!$D$6:$D$505,'Orders Log'!$C$6:$C$505,$A18)) | H18: =IF($A18="","",SUMIFS('Orders Log'!$V$6:$V$505,'Orders Log'!$C$6:$C$505,$A18)) | I18: =IF($A18="","",$H18-ROW()/1000000000)
E19: =IF($A19="","",$D19/60*Settings!$C$5) | F19: =IF($A19="","",$B19+$C19+$E19) | G19: =IF($A19="","",SUMIFS('Orders Log'!$D$6:$D$505,'Orders Log'!$C$6:$C$505,$A19)) | H19: =IF($A19="","",SUMIFS('Orders Log'!$V$6:$V$505,'Orders Log'!$C$6:$C$505,$A19)) | I19: =IF($A19="","",$H19-ROW()/1000000000)
E20: =IF($A20="","",$D20/60*Settings!$C$5) | F20: =IF($A20="","",$B20+$C20+$E20) | G20: =IF($A20="","",SUMIFS('Orders Log'!$D$6:$D$505,'Orders Log'!$C$6:$C$505,$A20)) | H20: =IF($A20="","",SUMIFS('Orders Log'!$V$6:$V$505,'Orders Log'!$C$6:$C$505,$A20)) | I20: =IF($A20="","",$H20-ROW()/1000000000)
E21: =IF($A21="","",$D21/60*Settings!$C$5) | F21: =IF($A21="","",$B21+$C21+$E21) | G21: =IF($A21="","",SUMIFS('Orders Log'!$D$6:$D$505,'Orders Log'!$C$6:$C$505,$A21)) | H21: =IF($A21="","",SUMIFS('Orders Log'!$V$6:$V$505,'Orders Log'!$C$6:$C$505,$A21)) | I21: =IF($A21="","",$H21-ROW()/1000000000)
... E54: =IF($A54="","",$D54/60*Settings!$C$5) | F54: =IF($A54="","",$B54+$C54+$E54) | G54: =IF($A54="","",SUMIFS('Orders Log'!$D$6:$D$505,'Orders Log'!$C$6:$C$505,$A54)) | H54: =IF($A54="","",SUMIFS('Orders Log'!$V$6:$V$505,'Orders Log'!$C$6:$C$505,$A54)) | I54: =IF($A54="","",$H54-ROW()/1000000000)

Sheet Price Calculator
A1: Price Calculator
A2: One item, Etsy vs Shopify side by side. Fill the yellow cells.
B3: INPUTS
B4: Product | C4: Ceramic Mug | E4: Pick from your Products tab.
B5: Your unit cost (from Products) | C5: =IFERROR(INDEX(Products!$F$5:$F$54,MATCH($C$4,Products!$A$5:$A$54,0)),0)
B6: Item price | C6: 32
B7: Shipping charged to the buyer | C7: 6.95 | E7: 0 for free shipping.
B8: Your shipping cost (label + postage) | C8: 7.2
B9: Sold via Etsy Offsite Ad? (Y/N) | C9: N | E9: Etsy only. Rate comes from Settings (15% or 12%).
B10: Expected Shopify orders per month | C10: 30 | E10: Spreads the Shopify plan cost over your orders.
B11: Target margin (for reverse mode) | C11: 0.3 | E11: Profit as % of what the buyer pays.
B13: Per order | C13: Etsy | D13: Shopify | E13: Shopify plan & provider are set on the Settings tab.
B14: Item price | C14: =$C$6 | D14: =$C$6
B15: Shipping charged | C15: =$C$7 | D15: =$C$7
B16: Order total (buyer pays) | C16: =C14+C15 | D16: =D14+D15
B17: Listing fee | C17: =Settings!$C$19 | D17: =0
B18: Transaction fee | C18: =Settings!$C$20*C16 | D18: =0
B19: Payment processing | C19: =Settings!$C$21*(1+Settings!$C$55)*C16+Settings!$C$22 | D19: =Settings!$C$14*D16+Settings!$C$15
B20: Offsite Ads fee | C20: =MIN(IF($C$9="Y",Settings!$C$12,0)*C16,Settings!$C$25) | D20: =0
B21: Shopify plan cost per order | C21: =0 | D21: =IF($C$10>0,Settings!$C$13/$C$10,0)
B22: Total fees | C22: =SUM(C17:C21) | D22: =SUM(D17:D21)
B23: Product cost | C23: =$C$5 | D23: =$C$5
B24: Shipping cost | C24: =$C$8 | D24: =$C$8
B25: NET PROFIT | C25: =C16-C22-C23-C24 | D25: =D16-D22-D23-D24
B26: Margin (profit / order total) | C26: =IF(C16>0,C25/C16,"") | D26: =IF(D16>0,D25/D16,"")
B27: Shopify minus Etsy profit per order | D27: =D25-C25
B29: REVERSE MODE: price to charge for your target margin
C30: Etsy | D30: Shopify
B31: Item price needed (shipping charged stays as entered) | C31: =IF(1-(Settings!$C$20+Settings!$C$21*(1+Settings!$C$55))-IF($C$9="Y",Settings!$C$12,0)-$C$11<=0,"Not reachable",MAX(0,ROUNDUP(IF(IF($C$9="Y",Settings!$C$12,0)*(Settings!$C$19+Settings!$C$22+$C$5+$C$8)/(1-(Settings!$C$20+Settings!$C$21*(1+Settings!$C$55))-IF($C$9="Y",Settings!$C$12,0)-$C$11)>Settings!$C$25,((Settings!$C$19+Settings!$C$22+$C$5+$C$8)+Settings!$C$25)/(1-(Settings!$C$20+Settings!$C$21*(1+Settings!$C$55))-$C$11),(Settings!$C$19+Settings!$C$22+$C$5+$C$8)/(1-(Settings!$C$20+Settings!$C$21*(1+Settings!$C$55))-IF($C$9="Y",Settings!$C$12,0)-$C$11))-$C$7,2))) | D31: =IF(1-Settings!$C$14-$C$11<=0,"Not reachable",MAX(0,ROUNDUP((Settings!$C$15+IF($C$10>0,Settings!$C$13/$C$10,0)+$C$5+$C$8)/(1-Settings!$C$14-$C$11)-$C$7,2))) | E31: Rounded up to the cent. Uses the same fees, costs and Offsite Ad setting as above.
B33: WHEN DOES SHOPIFY PAY OFF?
B34: Etsy fees per order at this price | C34: =C22
B35: Shopify fees per order, before the plan cost | C35: =D22-D21
B36: You save per order on Shopify | C36: =C34-C35
B37: Shopify plan cost per month (Settings) | C37: =Settings!$C$13
B38: Orders per month where Shopify's plan pays for itself | C38: =IF(C36<=0,"Never at this price",ROUNDUP(C37/C36,0))
B39: =IF(ISNUMBER(C38),"From "&C38&" orders a month at this price, Shopify's lower per-order fees cover its plan cost.","At this price Etsy's per-order fees are not higher than Shopify's, so the plan never pays for itself.")
B40: Leaves out the cost of bringing your own traffic to Shopify (ads, apps, theme) and Etsy Ads. Treat it as a floor, not a promise.

Sheet Orders Log
A1: Orders Log
A2: One row per order. Fill the yellow columns A-L; everything blue is worked out for you. Sales tax collected by Etsy is NOT revenue - leave it out.
A3: Product cost uses today's unit cost from the Products tab. Pre-sized for 500 orders (rows 6-505).
A5: Date | B5: Platform | C5: Product | D5: Qty | E5: Item price (each) | F5: Shipping charged | G5: Your shipping cost | H5: Discount ($ off order) | I5: Sold via Offsite Ad? (Etsy) | J5: Refunded? | K5: Partial refund $ (blank = full) | L5: Etsy fees credited back? | M5: Order total (buyer paid) | N5: Listing fee | O5: Transaction fee | P5: Payment processing | Q5: Offsite Ads fee | R5: Fee credit on refund | S5: Total fees | T5: Refund amount | U5: Product cost | V5: Net profit | W5: Margin | X5: Month
A6: 46235 | B6: Etsy | C6: Ceramic Mug | D6: 2 | E6: 32 | F6: 6.95 | G6: 7.2 | I6: N | J6: N | M6: =IF($A6="","",IF($D6="",1,$D6)*$E6+$F6-$H6) | N6: =IF($A6="","",IF($B6="Etsy",IF($D6="",1,$D6)*Settings!$C$19,0)) | O6: =IF($A6="","",IF($B6="Etsy",Settings!$C$20*($M6+IF(Settings!$C$54="Y",0,$H6)),0)) | P6: =IF($A6="","",IF($B6="Etsy",Settings!$C$21*$M6*(1+Settings!$C$55)+Settings!$C$22,IF($B6="Shopify",Settings!$C$14*$M6+Settings!$C$15,0))) | Q6: =IF($A6="","",IF(AND($B6="Etsy",$I6="Y"),MIN(Settings!$C$12*($M6+IF(Settings!$C$54="Y",0,$H6)),Settings!$C$25),0)) | R6: =IF($A6="","",IF(AND($B6="Etsy",$J6="Y",$L6="Y",$M6>0),($O6+Settings!$C$21*$M6*(1+Settings!$C$55)+IF(Settings!$C$59="Y",$Q6,0))*$T6/$M6+IF(AND(Settings!$C$58="Y",$T6>=$M6),Settings!$C$22,0),0)) | S6: =IF($A6="","",$N6+$O6+$P6+$Q6-$R6) | T6: =IF($A6="","",IF($J6="Y",IF($K6="",$M6,MIN($K6,$M6)),0)) | U6: =IF($A6="","",IF($D6="",1,$D6)*IFERROR(INDEX(Products!$F$5:$F$54,MATCH($C6,Products!$A$5:$A$54,0)),0)) | V6: =IF($A6="","",$M6-$T6-$S6-$U6-$G6) | W6: =IF($A6="","",IF($M6-$T6>0,$V6/($M6-$T6),"")) | X6: =IF($A6="","",DATE(YEAR($A6),MONTH($A6),1))
A7: 46237 | B7: Etsy | C7: Beaded Bracelet | D7: 1 | E7: 18 | F7: 0 | G7: 4 | I7: N | J7: N | M7: =IF($A7="","",IF($D7="",1,$D7)*$E7+$F7-$H7) | N7: =IF($A7="","",IF($B7="Etsy",IF($D7="",1,$D7)*Settings!$C$19,0)) | O7: =IF($A7="","",IF($B7="Etsy",Settings!$C$20*($M7+IF(Settings!$C$54="Y",0,$H7)),0)) | P7: =IF($A7="","",IF($B7="Etsy",Settings!$C$21*$M7*(1+Settings!$C$55)+Settings!$C$22,IF($B7="Shopify",Settings!$C$14*$M7+Settings!$C$15,0))) | Q7: =IF($A7="","",IF(AND($B7="Etsy",$I7="Y"),MIN(Settings!$C$12*($M7+IF(Settings!$C$54="Y",0,$H7)),Settings!$C$25),0)) | R7: =IF($A7="","",IF(AND($B7="Etsy",$J7="Y",$L7="Y",$M7>0),($O7+Settings!$C$21*$M7*(1+Settings!$C$55)+IF(Settings!$C$59="Y",$Q7,0))*$T7/$M7+IF(AND(Settings!$C$58="Y",$T7>=$M7),Settings!$C$22,0),0)) | S7: =IF($A7="","",$N7+$O7+$P7+$Q7-$R7) | T7: =IF($A7="","",IF($J7="Y",IF($K7="",$M7,MIN($K7,$M7)),0)) | U7: =IF($A7="","",IF($D7="",1,$D7)*IFERROR(INDEX(Products!$F$5:$F$54,MATCH($C7,Products!$A$5:$A$54,0)),0)) | V7: =IF($A7="","",$M7-$T7-$S7-$U7-$G7) | W7: =IF($A7="","",IF($M7-$T7>0,$V7/($M7-$T7),"")) | X7: =IF($A7="","",DATE(YEAR($A7),MONTH($A7),1))
A8: 46239 | B8: Etsy | C8: Linen Tote Bag | D8: 1 | E8: 28 | F8: 5.5 | G8: 5 | I8: Y | J8: N | M8: =IF($A8="","",IF($D8="",1,$D8)*$E8+$F8-$H8) | N8: =IF($A8="","",IF($B8="Etsy",IF($D8="",1,$D8)*Settings!$C$19,0)) | O8: =IF($A8="","",IF($B8="Etsy",Settings!$C$20*($M8+IF(Settings!$C$54="Y",0,$H8)),0)) | P8: =IF($A8="","",IF($B8="Etsy",Settings!$C$21*$M8*(1+Settings!$C$55)+Settings!$C$22,IF($B8="Shopify",Settings!$C$14*$M8+Settings!$C$15,0))) | Q8: =IF($A8="","",IF(AND($B8="Etsy",$I8="Y"),MIN(Settings!$C$12*($M8+IF(Settings!$C$54="Y",0,$H8)),Settings!$C$25),0)) | R8: =IF($A8="","",IF(AND($B8="Etsy",$J8="Y",$L8="Y",$M8>0),($O8+Settings!$C$21*$M8*(1+Settings!$C$55)+IF(Settings!$C$59="Y",$Q8,0))*$T8/$M8+IF(AND(Settings!$C$58="Y",$T8>=$M8),Settings!$C$22,0),0)) | S8: =IF($A8="","",$N8+$O8+$P8+$Q8-$R8) | T8: =IF($A8="","",IF($J8="Y",IF($K8="",$M8,MIN($K8,$M8)),0)) | U8: =IF($A8="","",IF($D8="",1,$D8)*IFERROR(INDEX(Products!$F$5:$F$54,MATCH($C8,Products!$A$5:$A$54,0)),0)) | V8: =IF($A8="","",$M8-$T8-$S8-$U8-$G8) | W8: =IF($A8="","",IF($M8-$T8>0,$V8/($M8-$T8),"")) | X8: =IF($A8="","",DATE(YEAR($A8),MONTH($A8),1))
A9: 46241 | B9: Shopify | C9: Art Print A4 | D9: 1 | E9: 15 | F9: 0 | G9: 1.8 | I9: N | J9: N | M9: =IF($A9="","",IF($D9="",1,$D9)*$E9+$F9-$H9) | N9: =IF($A9="","",IF($B9="Etsy",IF($D9="",1,$D9)*Settings!$C$19,0)) | O9: =IF($A9="","",IF($B9="Etsy",Settings!$C$20*($M9+IF(Settings!$C$54="Y",0,$H9)),0)) | P9: =IF($A9="","",IF($B9="Etsy",Settings!$C$21*$M9*(1+Settings!$C$55)+Settings!$C$22,IF($B9="Shopify",Settings!$C$14*$M9+Settings!$C$15,0))) | Q9: =IF($A9="","",IF(AND($B9="Etsy",$I9="Y"),MIN(Settings!$C$12*($M9+IF(Settings!$C$54="Y",0,$H9)),Settings!$C$25),0)) | R9: =IF($A9="","",IF(AND($B9="Etsy",$J9="Y",$L9="Y",$M9>0),($O9+Settings!$C$21*$M9*(1+Settings!$C$55)+IF(Settings!$C$59="Y",$Q9,0))*$T9/$M9+IF(AND(Settings!$C$58="Y",$T9>=$M9),Settings!$C$22,0),0)) | S9: =IF($A9="","",$N9+$O9+$P9+$Q9-$R9) | T9: =IF($A9="","",IF($J9="Y",IF($K9="",$M9,MIN($K9,$M9)),0)) | U9: =IF($A9="","",IF($D9="",1,$D9)*IFERROR(INDEX(Products!$F$5:$F$54,MATCH($C9,Products!$A$5:$A$54,0)),0)) | V9: =IF($A9="","",$M9-$T9-$S9-$U9-$G9) | W9: =IF($A9="","",IF($M9-$T9>0,$V9/($M9-$T9),"")) | X9: =IF($A9="","",DATE(YEAR($A9),MONTH($A9),1))
A10: 46243 | B10: Etsy | C10: Soy Candle 8oz | D10: 1 | E10: 24 | F10: 6 | G10: 6.5 | H10: 3 | I10: N | J10: N | M10: =IF($A10="","",IF($D10="",1,$D10)*$E10+$F10-$H10) | N10: =IF($A10="","",IF($B10="Etsy",IF($D10="",1,$D10)*Settings!$C$19,0)) | O10: =IF($A10="","",IF($B10="Etsy",Settings!$C$20*($M10+IF(Settings!$C$54="Y",0,$H10)),0)) | P10: =IF($A10="","",IF($B10="Etsy",Settings!$C$21*$M10*(1+Settings!$C$55)+Settings!$C$22,IF($B10="Shopify",Settings!$C$14*$M10+Settings!$C$15,0))) | Q10: =IF($A10="","",IF(AND($B10="Etsy",$I10="Y"),MIN(Settings!$C$12*($M10+IF(Settings!$C$54="Y",0,$H10)),Settings!$C$25),0)) | R10: =IF($A10="","",IF(AND($B10="Etsy",$J10="Y",$L10="Y",$M10>0),($O10+Settings!$C$21*$M10*(1+Settings!$C$55)+IF(Settings!$C$59="Y",$Q10,0))*$T10/$M10+IF(AND(Settings!$C$58="Y",$T10>=$M10),Settings!$C$22,0),0)) | S10: =IF($A10="","",$N10+$O10+$P10+$Q10-$R10) | T10: =IF($A10="","",IF($J10="Y",IF($K10="",$M10,MIN($K10,$M10)),0)) | U10: =IF($A10="","",IF($D10="",1,$D10)*IFERROR(INDEX(Products!$F$5:$F$54,MATCH($C10,Products!$A$5:$A$54,0)),0)) | V10: =IF($A10="","",$M10-$T10-$S10-$U10-$G10) | W10: =IF($A10="","",IF($M10-$T10>0,$V10/($M10-$T10),"")) | X10: =IF($A10="","",DATE(YEAR($A10),MONTH($A10),1))
A11: 46245 | B11: Etsy | C11: Ceramic Mug | D11: 1 | E11: 32 | F11: 6.95 | G11: 7.2 | I11: N | J11: N | M11: =IF($A11="","",IF($D11="",1,$D11)*$E11+$F11-$H11) | N11: =IF($A11="","",IF($B11="Etsy",IF($D11="",1,$D11)*Settings!$C$19,0)) | O11: =IF($A11="","",IF($B11="Etsy",Settings!$C$20*($M11+IF(Settings!$C$54="Y",0,$H11)),0)) | P11: =IF($A11="","",IF($B11="Etsy",Settings!$C$21*$M11*(1+Settings!$C$55)+Settings!$C$22,IF($B11="Shopify",Settings!$C$14*$M11+Settings!$C$15,0))) | Q11: =IF($A11="","",IF(AND($B11="Etsy",$I11="Y"),MIN(Settings!$C$12*($M11+IF(Settings!$C$54="Y",0,$H11)),Settings!$C$25),0)) | R11: =IF($A11="","",IF(AND($B11="Etsy",$J11="Y",$L11="Y",$M11>0),($O11+Settings!$C$21*$M11*(1+Settings!$C$55)+IF(Settings!$C$59="Y",$Q11,0))*$T11/$M11+IF(AND(Settings!$C$58="Y",$T11>=$M11),Settings!$C$22,0),0)) | S11: =IF($A11="","",$N11+$O11+$P11+$Q11-$R11) | T11: =IF($A11="","",IF($J11="Y",IF($K11="",$M11,MIN($K11,$M11)),0)) | U11: =IF($A11="","",IF($D11="",1,$D11)*IFERROR(INDEX(Products!$F$5:$F$54,MATCH($C11,Products!$A$5:$A$54,0)),0)) | V11: =IF($A11="","",$M11-$T11-$S11-$U11-$G11) | W11: =IF($A11="","",IF($M11-$T11>0,$V11/($M11-$T11),"")) | X11: =IF($A11="","",DATE(YEAR($A11),MONTH($A11),1))
A12: 46247 | B12: Etsy | C12: Beaded Bracelet | D12: 1 | E12: 18 | F12: 0 | G12: 4 | I12: N | J12: N | M12: =IF($A12="","",IF($D12="",1,$D12)*$E12+$F12-$H12) | N12: =IF($A12="","",IF($B12="Etsy",IF($D12="",1,$D12)*Settings!$C$19,0)) | O12: =IF($A12="","",IF($B12="Etsy",Settings!$C$20*($M12+IF(Settings!$C$54="Y",0,$H12)),0)) | P12: =IF($A12="","",IF($B12="Etsy",Settings!$C$21*$M12*(1+Settings!$C$55)+Settings!$C$22,IF($B12="Shopify",Settings!$C$14*$M12+Settings!$C$15,0))) | Q12: =IF($A12="","",IF(AND($B12="Etsy",$I12="Y"),MIN(Settings!$C$12*($M12+IF(Settings!$C$54="Y",0,$H12)),Settings!$C$25),0)) | R12: =IF($A12="","",IF(AND($B12="Etsy",$J12="Y",$L12="Y",$M12>0),($O12+Settings!$C$21*$M12*(1+Settings!$C$55)+IF(Settings!$C$59="Y",$Q12,0))*$T12/$M12+IF(AND(Settings!$C$58="Y",$T12>=$M12),Settings!$C$22,0),0)) | S12: =IF($A12="","",$N12+$O12+$P12+$Q12-$R12) | T12: =IF($A12="","",IF($J12="Y",IF($K12="",$M12,MIN($K12,$M12)),0)) | U12: =IF($A12="","",IF($D12="",1,$D12)*IFERROR(INDEX(Products!$F$5:$F$54,MATCH($C12,Products!$A$5:$A$54,0)),0)) | V12: =IF($A12="","",$M12-$T12-$S12-$U12-$G12) | W12: =IF($A12="","",IF($M12-$T12>0,$V12/($M12-$T12),"")) | X12: =IF($A12="","",DATE(YEAR($A12),MONTH($A12),1))
A13: 46249 | B13: Shopify | C13: Linen Tote Bag | D13: 2 | E13: 28 | F13: 5.5 | G13: 5 | I13: N | J13: N | M13: =IF($A13="","",IF($D13="",1,$D13)*$E13+$F13-$H13) | N13: =IF($A13="","",IF($B13="Etsy",IF($D13="",1,$D13)*Settings!$C$19,0)) | O13: =IF($A13="","",IF($B13="Etsy",Settings!$C$20*($M13+IF(Settings!$C$54="Y",0,$H13)),0)) | P13: =IF($A13="","",IF($B13="Etsy",Settings!$C$21*$M13*(1+Settings!$C$55)+Settings!$C$22,IF($B13="Shopify",Settings!$C$14*$M13+Settings!$C$15,0))) | Q13: =IF($A13="","",IF(AND($B13="Etsy",$I13="Y"),MIN(Settings!$C$12*($M13+IF(Settings!$C$54="Y",0,$H13)),Settings!$C$25),0)) | R13: =IF($A13="","",IF(AND($B13="Etsy",$J13="Y",$L13="Y",$M13>0),($O13+Settings!$C$21*$M13*(1+Settings!$C$55)+IF(Settings!$C$59="Y",$Q13,0))*$T13/$M13+IF(AND(Settings!$C$58="Y",$T13>=$M13),Settings!$C$22,0),0)) | S13: =IF($A13="","",$N13+$O13+$P13+$Q13-$R13) | T13: =IF($A13="","",IF($J13="Y",IF($K13="",$M13,MIN($K13,$M13)),0)) | U13: =IF($A13="","",IF($D13="",1,$D13)*IFERROR(INDEX(Products!$F$5:$F$54,MATCH($C13,Products!$A$5:$A$54,0)),0)) | V13: =IF($A13="","",$M13-$T13-$S13-$U13-$G13) | W13: =IF($A13="","",IF($M13-$T13>0,$V13/($M13-$T13),"")) | X13: =IF($A13="","",DATE(YEAR($A13),MONTH($A13),1))
A14: 46251 | B14: Etsy | C14: Art Print A4 | D14: 1 | E14: 15 | F14: 0 | G14: 1.8 | I14: Y | J14: N | M14: =IF($A14="","",IF($D14="",1,$D14)*$E14+$F14-$H14) | N14: =IF($A14="","",IF($B14="Etsy",IF($D14="",1,$D14)*Settings!$C$19,0)) | O14: =IF($A14="","",IF($B14="Etsy",Settings!$C$20*($M14+IF(Settings!$C$54="Y",0,$H14)),0)) | P14: =IF($A14="","",IF($B14="Etsy",Settings!$C$21*$M14*(1+Settings!$C$55)+Settings!$C$22,IF($B14="Shopify",Settings!$C$14*$M14+Settings!$C$15,0))) | Q14: =IF($A14="","",IF(AND($B14="Etsy",$I14="Y"),MIN(Settings!$C$12*($M14+IF(Settings!$C$54="Y",0,$H14)),Settings!$C$25),0)) | R14: =IF($A14="","",IF(AND($B14="Etsy",$J14="Y",$L14="Y",$M14>0),($O14+Settings!$C$21*$M14*(1+Settings!$C$55)+IF(Settings!$C$59="Y",$Q14,0))*$T14/$M14+IF(AND(Settings!$C$58="Y",$T14>=$M14),Settings!$C$22,0),0)) | S14: =IF($A14="","",$N14+$O14+$P14+$Q14-$R14) | T14: =IF($A14="","",IF($J14="Y",IF($K14="",$M14,MIN($K14,$M14)),0)) | U14: =IF($A14="","",IF($D14="",1,$D14)*IFERROR(INDEX(Products!$F$5:$F$54,MATCH($C14,Products!$A$5:$A$54,0)),0)) | V14: =IF($A14="","",$M14-$T14-$S14-$U14-$G14) | W14: =IF($A14="","",IF($M14-$T14>0,$V14/($M14-$T14),"")) | X14: =IF($A14="","",DATE(YEAR($A14),MONTH($A14),1))
A15: 46253 | B15: Etsy | C15: Soy Candle 8oz | D15: 1 | E15: 24 | F15: 6 | G15: 6.5 | I15: N | J15: N | M15: =IF($A15="","",IF($D15="",1,$D15)*$E15+$F15-$H15) | N15: =IF($A15="","",IF($B15="Etsy",IF($D15="",1,$D15)*Settings!$C$19,0)) | O15: =IF($A15="","",IF($B15="Etsy",Settings!$C$20*($M15+IF(Settings!$C$54="Y",0,$H15)),0)) | P15: =IF($A15="","",IF($B15="Etsy",Settings!$C$21*$M15*(1+Settings!$C$55)+Settings!$C$22,IF($B15="Shopify",Settings!$C$14*$M15+Settings!$C$15,0))) | Q15: =IF($A15="","",IF(AND($B15="Etsy",$I15="Y"),MIN(Settings!$C$12*($M15+IF(Settings!$C$54="Y",0,$H15)),Settings!$C$25),0)) | R15: =IF($A15="","",IF(AND($B15="Etsy",$J15="Y",$L15="Y",$M15>0),($O15+Settings!$C$21*$M15*(1+Settings!$C$55)+IF(Settings!$C$59="Y",$Q15,0))*$T15/$M15+IF(AND(Settings!$C$58="Y",$T15>=$M15),Settings!$C$22,0),0)) | S15: =IF($A15="","",$N15+$O15+$P15+$Q15-$R15) | T15: =IF($A15="","",IF($J15="Y",IF($K15="",$M15,MIN($K15,$M15)),0)) | U15: =IF($A15="","",IF($D15="",1,$D15)*IFERROR(INDEX(Products!$F$5:$F$54,MATCH($C15,Products!$A$5:$A$54,0)),0)) | V15: =IF($A15="","",$M15-$T15-$S15-$U15-$G15) | W15: =IF($A15="","",IF($M15-$T15>0,$V15/($M15-$T15),"")) | X15: =IF($A15="","",DATE(YEAR($A15),MONTH($A15),1))
A16: 46266 | B16: Etsy | C16: Ceramic Mug | D16: 1 | E16: 32 | F16: 6.95 | G16: 7.2 | I16: N | J16: N | M16: =IF($A16="","",IF($D16="",1,$D16)*$E16+$F16-$H16) | N16: =IF($A16="","",IF($B16="Etsy",IF($D16="",1,$D16)*Settings!$C$19,0)) | O16: =IF($A16="","",IF($B16="Etsy",Settings!$C$20*($M16+IF(Settings!$C$54="Y",0,$H16)),0)) | P16: =IF($A16="","",IF($B16="Etsy",Settings!$C$21*$M16*(1+Settings!$C$55)+Settings!$C$22,IF($B16="Shopify",Settings!$C$14*$M16+Settings!$C$15,0))) | Q16: =IF($A16="","",IF(AND($B16="Etsy",$I16="Y"),MIN(Settings!$C$12*($M16+IF(Settings!$C$54="Y",0,$H16)),Settings!$C$25),0)) | R16: =IF($A16="","",IF(AND($B16="Etsy",$J16="Y",$L16="Y",$M16>0),($O16+Settings!$C$21*$M16*(1+Settings!$C$55)+IF(Settings!$C$59="Y",$Q16,0))*$T16/$M16+IF(AND(Settings!$C$58="Y",$T16>=$M16),Settings!$C$22,0),0)) | S16: =IF($A16="","",$N16+$O16+$P16+$Q16-$R16) | T16: =IF($A16="","",IF($J16="Y",IF($K16="",$M16,MIN($K16,$M16)),0)) | U16: =IF($A16="","",IF($D16="",1,$D16)*IFERROR(INDEX(Products!$F$5:$F$54,MATCH($C16,Products!$A$5:$A$54,0)),0)) | V16: =IF($A16="","",$M16-$T16-$S16-$U16-$G16) | W16: =IF($A16="","",IF($M16-$T16>0,$V16/($M16-$T16),"")) | X16: =IF($A16="","",DATE(YEAR($A16),MONTH($A16),1))
A17: 46268 | B17: Shopify | C17: Beaded Bracelet | D17: 1 | E17: 18 | F17: 0 | G17: 4 | I17: N | J17: Y | L17: Y | M17: =IF($A17="","",IF($D17="",1,$D17)*$E17+$F17-$H17) | N17: =IF($A17="","",IF($B17="Etsy",IF($D17="",1,$D17)*Settings!$C$19,0)) | O17: =IF($A17="","",IF($B17="Etsy",Settings!$C$20*($M17+IF(Settings!$C$54="Y",0,$H17)),0)) | P17: =IF($A17="","",IF($B17="Etsy",Settings!$C$21*$M17*(1+Settings!$C$55)+Settings!$C$22,IF($B17="Shopify",Settings!$C$14*$M17+Settings!$C$15,0))) | Q17: =IF($A17="","",IF(AND($B17="Etsy",$I17="Y"),MIN(Settings!$C$12*($M17+IF(Settings!$C$54="Y",0,$H17)),Settings!$C$25),0)) | R17: =IF($A17="","",IF(AND($B17="Etsy",$J17="Y",$L17="Y",$M17>0),($O17+Settings!$C$21*$M17*(1+Settings!$C$55)+IF(Settings!$C$59="Y",$Q17,0))*$T17/$M17+IF(AND(Settings!$C$58="Y",$T17>=$M17),Settings!$C$22,0),0)) | S17: =IF($A17="","",$N17+$O17+$P17+$Q17-$R17) | T17: =IF($A17="","",IF($J17="Y",IF($K17="",$M17,MIN($K17,$M17)),0)) | U17: =IF($A17="","",IF($D17="",1,$D17)*IFERROR(INDEX(Products!$F$5:$F$54,MATCH($C17,Products!$A$5:$A$54,0)),0)) | V17: =IF($A17="","",$M17-$T17-$S17-$U17-$G17) | W17: =IF($A17="","",IF($M17-$T17>0,$V17/($M17-$T17),"")) | X17: =IF($A17="","",DATE(YEAR($A17),MONTH($A17),1))
A18: 46270 | B18: Etsy | C18: Linen Tote Bag | D18: 1 | E18: 28 | F18: 5.5 | G18: 5 | I18: N | J18: N | M18: =IF($A18="","",IF($D18="",1,$D18)*$E18+$F18-$H18) | N18: =IF($A18="","",IF($B18="Etsy",IF($D18="",1,$D18)*Settings!$C$19,0)) | O18: =IF($A18="","",IF($B18="Etsy",Settings!$C$20*($M18+IF(Settings!$C$54="Y",0,$H18)),0)) | P18: =IF($A18="","",IF($B18="Etsy",Settings!$C$21*$M18*(1+Settings!$C$55)+Settings!$C$22,IF($B18="Shopify",Settings!$C$14*$M18+Settings!$C$15,0))) | Q18: =IF($A18="","",IF(AND($B18="Etsy",$I18="Y"),MIN(Settings!$C$12*($M18+IF(Settings!$C$54="Y",0,$H18)),Settings!$C$25),0)) | R18: =IF($A18="","",IF(AND($B18="Etsy",$J18="Y",$L18="Y",$M18>0),($O18+Settings!$C$21*$M18*(1+Settings!$C$55)+IF(Settings!$C$59="Y",$Q18,0))*$T18/$M18+IF(AND(Settings!$C$58="Y",$T18>=$M18),Settings!$C$22,0),0)) | S18: =IF($A18="","",$N18+$O18+$P18+$Q18-$R18) | T18: =IF($A18="","",IF($J18="Y",IF($K18="",$M18,MIN($K18,$M18)),0)) | U18: =IF($A18="","",IF($D18="",1,$D18)*IFERROR(INDEX(Products!$F$5:$F$54,MATCH($C18,Products!$A$5:$A$54,0)),0)) | V18: =IF($A18="","",$M18-$T18-$S18-$U18-$G18) | W18: =IF($A18="","",IF($M18-$T18>0,$V18/($M18-$T18),"")) | X18: =IF($A18="","",DATE(YEAR($A18),MONTH($A18),1))
A19: 46272 | B19: Etsy | C19: Art Print A4 | D19: 1 | E19: 15 | F19: 0 | G19: 1.8 | H19: 3 | I19: N | J19: N | M19: =IF($A19="","",IF($D19="",1,$D19)*$E19+$F19-$H19) | N19: =IF($A19="","",IF($B19="Etsy",IF($D19="",1,$D19)*Settings!$C$19,0)) | O19: =IF($A19="","",IF($B19="Etsy",Settings!$C$20*($M19+IF(Settings!$C$54="Y",0,$H19)),0)) | P19: =IF($A19="","",IF($B19="Etsy",Settings!$C$21*$M19*(1+Settings!$C$55)+Settings!$C$22,IF($B19="Shopify",Settings!$C$14*$M19+Settings!$C$15,0))) | Q19: =IF($A19="","",IF(AND($B19="Etsy",$I19="Y"),MIN(Settings!$C$12*($M19+IF(Settings!$C$54="Y",0,$H19)),Settings!$C$25),0)) | R19: =IF($A19="","",IF(AND($B19="Etsy",$J19="Y",$L19="Y",$M19>0),($O19+Settings!$C$21*$M19*(1+Settings!$C$55)+IF(Settings!$C$59="Y",$Q19,0))*$T19/$M19+IF(AND(Settings!$C$58="Y",$T19>=$M19),Settings!$C$22,0),0)) | S19: =IF($A19="","",$N19+$O19+$P19+$Q19-$R19) | T19: =IF($A19="","",IF($J19="Y",IF($K19="",$M19,MIN($K19,$M19)),0)) | U19: =IF($A19="","",IF($D19="",1,$D19)*IFERROR(INDEX(Products!$F$5:$F$54,MATCH($C19,Products!$A$5:$A$54,0)),0)) | V19: =IF($A19="","",$M19-$T19-$S19-$U19-$G19) | W19: =IF($A19="","",IF($M19-$T19>0,$V19/($M19-$T19),"")) | X19: =IF($A19="","",DATE(YEAR($A19),MONTH($A19),1))
A20: 46274 | B20: Etsy | C20: Soy Candle 8oz | D20: 2 | E20: 24 | F20: 6 | G20: 6.5 | I20: Y | J20: N | M20: =IF($A20="","",IF($D20="",1,$D20)*$E20+$F20-$H20) | N20: =IF($A20="","",IF($B20="Etsy",IF($D20="",1,$D20)*Settings!$C$19,0)) | O20: =IF($A20="","",IF($B20="Etsy",Settings!$C$20*($M20+IF(Settings!$C$54="Y",0,$H20)),0)) | P20: =IF($A20="","",IF($B20="Etsy",Settings!$C$21*$M20*(1+Settings!$C$55)+Settings!$C$22,IF($B20="Shopify",Settings!$C$14*$M20+Settings!$C$15,0))) | Q20: =IF($A20="","",IF(AND($B20="Etsy",$I20="Y"),MIN(Settings!$C$12*($M20+IF(Settings!$C$54="Y",0,$H20)),Settings!$C$25),0)) | R20: =IF($A20="","",IF(AND($B20="Etsy",$J20="Y",$L20="Y",$M20>0),($O20+Settings!$C$21*$M20*(1+Settings!$C$55)+IF(Settings!$C$59="Y",$Q20,0))*$T20/$M20+IF(AND(Settings!$C$58="Y",$T20>=$M20),Settings!$C$22,0),0)) | S20: =IF($A20="","",$N20+$O20+$P20+$Q20-$R20) | T20: =IF($A20="","",IF($J20="Y",IF($K20="",$M20,MIN($K20,$M20)),0)) | U20: =IF($A20="","",IF($D20="",1,$D20)*IFERROR(INDEX(Products!$F$5:$F$54,MATCH($C20,Products!$A$5:$A$54,0)),0)) | V20: =IF($A20="","",$M20-$T20-$S20-$U20-$G20) | W20: =IF($A20="","",IF($M20-$T20>0,$V20/($M20-$T20),"")) | X20: =IF($A20="","",DATE(YEAR($A20),MONTH($A20),1))
A21: 46276 | B21: Shopify | C21: Ceramic Mug | D21: 1 | E21: 32 | F21: 6.95 | G21: 7.2 | I21: N | J21: N | M21: =IF($A21="","",IF($D21="",1,$D21)*$E21+$F21-$H21) | N21: =IF($A21="","",IF($B21="Etsy",IF($D21="",1,$D21)*Settings!$C$19,0)) | O21: =IF($A21="","",IF($B21="Etsy",Settings!$C$20*($M21+IF(Settings!$C$54="Y",0,$H21)),0)) | P21: =IF($A21="","",IF($B21="Etsy",Settings!$C$21*$M21*(1+Settings!$C$55)+Settings!$C$22,IF($B21="Shopify",Settings!$C$14*$M21+Settings!$C$15,0))) | Q21: =IF($A21="","",IF(AND($B21="Etsy",$I21="Y"),MIN(Settings!$C$12*($M21+IF(Settings!$C$54="Y",0,$H21)),Settings!$C$25),0)) | R21: =IF($A21="","",IF(AND($B21="Etsy",$J21="Y",$L21="Y",$M21>0),($O21+Settings!$C$21*$M21*(1+Settings!$C$55)+IF(Settings!$C$59="Y",$Q21,0))*$T21/$M21+IF(AND(Settings!$C$58="Y",$T21>=$M21),Settings!$C$22,0),0)) | S21: =IF($A21="","",$N21+$O21+$P21+$Q21-$R21) | T21: =IF($A21="","",IF($J21="Y",IF($K21="",$M21,MIN($K21,$M21)),0)) | U21: =IF($A21="","",IF($D21="",1,$D21)*IFERROR(INDEX(Products!$F$5:$F$54,MATCH($C21,Products!$A$5:$A$54,0)),0)) | V21: =IF($A21="","",$M21-$T21-$S21-$U21-$G21) | W21: =IF($A21="","",IF($M21-$T21>0,$V21/($M21-$T21),"")) | X21: =IF($A21="","",DATE(YEAR($A21),MONTH($A21),1))
A22: 46278 | B22: Etsy | C22: Beaded Bracelet | D22: 1 | E22: 18 | F22: 0 | G22: 4 | I22: N | J22: N | M22: =IF($A22="","",IF($D22="",1,$D22)*$E22+$F22-$H22) | N22: =IF($A22="","",IF($B22="Etsy",IF($D22="",1,$D22)*Settings!$C$19,0)) | O22: =IF($A22="","",IF($B22="Etsy",Settings!$C$20*($M22+IF(Settings!$C$54="Y",0,$H22)),0)) | P22: =IF($A22="","",IF($B22="Etsy",Settings!$C$21*$M22*(1+Settings!$C$55)+Settings!$C$22,IF($B22="Shopify",Settings!$C$14*$M22+Settings!$C$15,0))) | Q22: =IF($A22="","",IF(AND($B22="Etsy",$I22="Y"),MIN(Settings!$C$12*($M22+IF(Settings!$C$54="Y",0,$H22)),Settings!$C$25),0)) | R22: =IF($A22="","",IF(AND($B22="Etsy",$J22="Y",$L22="Y",$M22>0),($O22+Settings!$C$21*$M22*(1+Settings!$C$55)+IF(Settings!$C$59="Y",$Q22,0))*$T22/$M22+IF(AND(Settings!$C$58="Y",$T22>=$M22),Settings!$C$22,0),0)) | S22: =IF($A22="","",$N22+$O22+$P22+$Q22-$R22) | T22: =IF($A22="","",IF($J22="Y",IF($K22="",$M22,MIN($K22,$M22)),0)) | U22: =IF($A22="","",IF($D22="",1,$D22)*IFERROR(INDEX(Products!$F$5:$F$54,MATCH($C22,Products!$A$5:$A$54,0)),0)) | V22: =IF($A22="","",$M22-$T22-$S22-$U22-$G22) | W22: =IF($A22="","",IF($M22-$T22>0,$V22/($M22-$T22),"")) | X22: =IF($A22="","",DATE(YEAR($A22),MONTH($A22),1))
A23: 46280 | B23: Etsy | C23: Linen Tote Bag | D23: 1 | E23: 28 | F23: 5.5 | G23: 5 | I23: N | J23: N | M23: =IF($A23="","",IF($D23="",1,$D23)*$E23+$F23-$H23) | N23: =IF($A23="","",IF($B23="Etsy",IF($D23="",1,$D23)*Settings!$C$19,0)) | O23: =IF($A23="","",IF($B23="Etsy",Settings!$C$20*($M23+IF(Settings!$C$54="Y",0,$H23)),0)) | P23: =IF($A23="","",IF($B23="Etsy",Settings!$C$21*$M23*(1+Settings!$C$55)+Settings!$C$22,IF($B23="Shopify",Settings!$C$14*$M23+Settings!$C$15,0))) | Q23: =IF($A23="","",IF(AND($B23="Etsy",$I23="Y"),MIN(Settings!$C$12*($M23+IF(Settings!$C$54="Y",0,$H23)),Settings!$C$25),0)) | R23: =IF($A23="","",IF(AND($B23="Etsy",$J23="Y",$L23="Y",$M23>0),($O23+Settings!$C$21*$M23*(1+Settings!$C$55)+IF(Settings!$C$59="Y",$Q23,0))*$T23/$M23+IF(AND(Settings!$C$58="Y",$T23>=$M23),Settings!$C$22,0),0)) | S23: =IF($A23="","",$N23+$O23+$P23+$Q23-$R23) | T23: =IF($A23="","",IF($J23="Y",IF($K23="",$M23,MIN($K23,$M23)),0)) | U23: =IF($A23="","",IF($D23="",1,$D23)*IFERROR(INDEX(Products!$F$5:$F$54,MATCH($C23,Products!$A$5:$A$54,0)),0)) | V23: =IF($A23="","",$M23-$T23-$S23-$U23-$G23) | W23: =IF($A23="","",IF($M23-$T23>0,$V23/($M23-$T23),"")) | X23: =IF($A23="","",DATE(YEAR($A23),MONTH($A23),1))
A24: 46282 | B24: Etsy | C24: Art Print A4 | D24: 1 | E24: 15 | F24: 0 | G24: 1.8 | I24: N | J24: N | M24: =IF($A24="","",IF($D24="",1,$D24)*$E24+$F24-$H24) | N24: =IF($A24="","",IF($B24="Etsy",IF($D24="",1,$D24)*Settings!$C$19,0)) | O24: =IF($A24="","",IF($B24="Etsy",Settings!$C$20*($M24+IF(Settings!$C$54="Y",0,$H24)),0)) | P24: =IF($A24="","",IF($B24="Etsy",Settings!$C$21*$M24*(1+Settings!$C$55)+Settings!$C$22,IF($B24="Shopify",Settings!$C$14*$M24+Settings!$C$15,0))) | Q24: =IF($A24="","",IF(AND($B24="Etsy",$I24="Y"),MIN(Settings!$C$12*($M24+IF(Settings!$C$54="Y",0,$H24)),Settings!$C$25),0)) | R24: =IF($A24="","",IF(AND($B24="Etsy",$J24="Y",$L24="Y",$M24>0),($O24+Settings!$C$21*$M24*(1+Settings!$C$55)+IF(Settings!$C$59="Y",$Q24,0))*$T24/$M24+IF(AND(Settings!$C$58="Y",$T24>=$M24),Settings!$C$22,0),0)) | S24: =IF($A24="","",$N24+$O24+$P24+$Q24-$R24) | T24: =IF($A24="","",IF($J24="Y",IF($K24="",$M24,MIN($K24,$M24)),0)) | U24: =IF($A24="","",IF($D24="",1,$D24)*IFERROR(INDEX(Products!$F$5:$F$54,MATCH($C24,Products!$A$5:$A$54,0)),0)) | V24: =IF($A24="","",$M24-$T24-$S24-$U24-$G24) | W24: =IF($A24="","",IF($M24-$T24>0,$V24/($M24-$T24),"")) | X24: =IF($A24="","",DATE(YEAR($A24),MONTH($A24),1))
A25: 46284 | B25: Shopify | C25: Soy Candle 8oz | D25: 1 | E25: 24 | F25: 6 | G25: 6.5 | I25: N | J25: N | M25: =IF($A25="","",IF($D25="",1,$D25)*$E25+$F25-$H25) | N25: =IF($A25="","",IF($B25="Etsy",IF($D25="",1,$D25)*Settings!$C$19,0)) | O25: =IF($A25="","",IF($B25="Etsy",Settings!$C$20*($M25+IF(Settings!$C$54="Y",0,$H25)),0)) | P25: =IF($A25="","",IF($B25="Etsy",Settings!$C$21*$M25*(1+Settings!$C$55)+Settings!$C$22,IF($B25="Shopify",Settings!$C$14*$M25+Settings!$C$15,0))) | Q25: =IF($A25="","",IF(AND($B25="Etsy",$I25="Y"),MIN(Settings!$C$12*($M25+IF(Settings!$C$54="Y",0,$H25)),Settings!$C$25),0)) | R25: =IF($A25="","",IF(AND($B25="Etsy",$J25="Y",$L25="Y",$M25>0),($O25+Settings!$C$21*$M25*(1+Settings!$C$55)+IF(Settings!$C$59="Y",$Q25,0))*$T25/$M25+IF(AND(Settings!$C$58="Y",$T25>=$M25),Settings!$C$22,0),0)) | S25: =IF($A25="","",$N25+$O25+$P25+$Q25-$R25) | T25: =IF($A25="","",IF($J25="Y",IF($K25="",$M25,MIN($K25,$M25)),0)) | U25: =IF($A25="","",IF($D25="",1,$D25)*IFERROR(INDEX(Products!$F$5:$F$54,MATCH($C25,Products!$A$5:$A$54,0)),0)) | V25: =IF($A25="","",$M25-$T25-$S25-$U25-$G25) | W25: =IF($A25="","",IF($M25-$T25>0,$V25/($M25-$T25),"")) | X25: =IF($A25="","",DATE(YEAR($A25),MONTH($A25),1))
A26: 46296 | B26: Etsy | C26: Ceramic Mug | D26: 1 | E26: 32 | F26: 6.95 | G26: 7.2 | I26: Y | J26: Y | K26: 8 | L26: Y | M26: =IF($A26="","",IF($D26="",1,$D26)*$E26+$F26-$H26) | N26: =IF($A26="","",IF($B26="Etsy",IF($D26="",1,$D26)*Settings!$C$19,0)) | O26: =IF($A26="","",IF($B26="Etsy",Settings!$C$20*($M26+IF(Settings!$C$54="Y",0,$H26)),0)) | P26: =IF($A26="","",IF($B26="Etsy",Settings!$C$21*$M26*(1+Settings!$C$55)+Settings!$C$22,IF($B26="Shopify",Settings!$C$14*$M26+Settings!$C$15,0))) | Q26: =IF($A26="","",IF(AND($B26="Etsy",$I26="Y"),MIN(Settings!$C$12*($M26+IF(Settings!$C$54="Y",0,$H26)),Settings!$C$25),0)) | R26: =IF($A26="","",IF(AND($B26="Etsy",$J26="Y",$L26="Y",$M26>0),($O26+Settings!$C$21*$M26*(1+Settings!$C$55)+IF(Settings!$C$59="Y",$Q26,0))*$T26/$M26+IF(AND(Settings!$C$58="Y",$T26>=$M26),Settings!$C$22,0),0)) | S26: =IF($A26="","",$N26+$O26+$P26+$Q26-$R26) | T26: =IF($A26="","",IF($J26="Y",IF($K26="",$M26,MIN($K26,$M26)),0)) | U26: =IF($A26="","",IF($D26="",1,$D26)*IFERROR(INDEX(Products!$F$5:$F$54,MATCH($C26,Products!$A$5:$A$54,0)),0)) | V26: =IF($A26="","",$M26-$T26-$S26-$U26-$G26) | W26: =IF($A26="","",IF($M26-$T26>0,$V26/($M26-$T26),"")) | X26: =IF($A26="","",DATE(YEAR($A26),MONTH($A26),1))
A27: 46298 | B27: Etsy | C27: Beaded Bracelet | D27: 2 | E27: 18 | F27: 0 | G27: 4 | I27: N | J27: N | M27: =IF($A27="","",IF($D27="",1,$D27)*$E27+$F27-$H27) | N27: =IF($A27="","",IF($B27="Etsy",IF($D27="",1,$D27)*Settings!$C$19,0)) | O27: =IF($A27="","",IF($B27="Etsy",Settings!$C$20*($M27+IF(Settings!$C$54="Y",0,$H27)),0)) | P27: =IF($A27="","",IF($B27="Etsy",Settings!$C$21*$M27*(1+Settings!$C$55)+Settings!$C$22,IF($B27="Shopify",Settings!$C$14*$M27+Settings!$C$15,0))) | Q27: =IF($A27="","",IF(AND($B27="Etsy",$I27="Y"),MIN(Settings!$C$12*($M27+IF(Settings!$C$54="Y",0,$H27)),Settings!$C$25),0)) | R27: =IF($A27="","",IF(AND($B27="Etsy",$J27="Y",$L27="Y",$M27>0),($O27+Settings!$C$21*$M27*(1+Settings!$C$55)+IF(Settings!$C$59="Y",$Q27,0))*$T27/$M27+IF(AND(Settings!$C$58="Y",$T27>=$M27),Settings!$C$22,0),0)) | S27: =IF($A27="","",$N27+$O27+$P27+$Q27-$R27) | T27: =IF($A27="","",IF($J27="Y",IF($K27="",$M27,MIN($K27,$M27)),0)) | U27: =IF($A27="","",IF($D27="",1,$D27)*IFERROR(INDEX(Products!$F$5:$F$54,MATCH($C27,Products!$A$5:$A$54,0)),0)) | V27: =IF($A27="","",$M27-$T27-$S27-$U27-$G27) | W27: =IF($A27="","",IF($M27-$T27>0,$V27/($M27-$T27),"")) | X27: =IF($A27="","",DATE(YEAR($A27),MONTH($A27),1))
A28: 46300 | B28: Etsy | C28: Linen Tote Bag | D28: 1 | E28: 28 | F28: 5.5 | G28: 5 | H28: 3 | I28: N | J28: N | M28: =IF($A28="","",IF($D28="",1,$D28)*$E28+$F28-$H28) | N28: =IF($A28="","",IF($B28="Etsy",IF($D28="",1,$D28)*Settings!$C$19,0)) | O28: =IF($A28="","",IF($B28="Etsy",Settings!$C$20*($M28+IF(Settings!$C$54="Y",0,$H28)),0)) | P28: =IF($A28="","",IF($B28="Etsy",Settings!$C$21*$M28*(1+Settings!$C$55)+Settings!$C$22,IF($B28="Shopify",Settings!$C$14*$M28+Settings!$C$15,0))) | Q28: =IF($A28="","",IF(AND($B28="Etsy",$I28="Y"),MIN(Settings!$C$12*($M28+IF(Settings!$C$54="Y",0,$H28)),Settings!$C$25),0)) | R28: =IF($A28="","",IF(AND($B28="Etsy",$J28="Y",$L28="Y",$M28>0),($O28+Settings!$C$21*$M28*(1+Settings!$C$55)+IF(Settings!$C$59="Y",$Q28,0))*$T28/$M28+IF(AND(Settings!$C$58="Y",$T28>=$M28),Settings!$C$22,0),0)) | S28: =IF($A28="","",$N28+$O28+$P28+$Q28-$R28) | T28: =IF($A28="","",IF($J28="Y",IF($K28="",$M28,MIN($K28,$M28)),0)) | U28: =IF($A28="","",IF($D28="",1,$D28)*IFERROR(INDEX(Products!$F$5:$F$54,MATCH($C28,Products!$A$5:$A$54,0)),0)) | V28: =IF($A28="","",$M28-$T28-$S28-$U28-$G28) | W28: =IF($A28="","",IF($M28-$T28>0,$V28/($M28-$T28),"")) | X28: =IF($A28="","",DATE(YEAR($A28),MONTH($A28),1))
A29: 46302 | B29: Shopify | C29: Art Print A4 | D29: 1 | E29: 15 | F29: 0 | G29: 1.8 | I29: N | J29: N | M29: =IF($A29="","",IF($D29="",1,$D29)*$E29+$F29-$H29) | N29: =IF($A29="","",IF($B29="Etsy",IF($D29="",1,$D29)*Settings!$C$19,0)) | O29: =IF($A29="","",IF($B29="Etsy",Settings!$C$20*($M29+IF(Settings!$C$54="Y",0,$H29)),0)) | P29: =IF($A29="","",IF($B29="Etsy",Settings!$C$21*$M29*(1+Settings!$C$55)+Settings!$C$22,IF($B29="Shopify",Settings!$C$14*$M29+Settings!$C$15,0))) | Q29: =IF($A29="","",IF(AND($B29="Etsy",$I29="Y"),MIN(Settings!$C$12*($M29+IF(Settings!$C$54="Y",0,$H29)),Settings!$C$25),0)) | R29: =IF($A29="","",IF(AND($B29="Etsy",$J29="Y",$L29="Y",$M29>0),($O29+Settings!$C$21*$M29*(1+Settings!$C$55)+IF(Settings!$C$59="Y",$Q29,0))*$T29/$M29+IF(AND(Settings!$C$58="Y",$T29>=$M29),Settings!$C$22,0),0)) | S29: =IF($A29="","",$N29+$O29+$P29+$Q29-$R29) | T29: =IF($A29="","",IF($J29="Y",IF($K29="",$M29,MIN($K29,$M29)),0)) | U29: =IF($A29="","",IF($D29="",1,$D29)*IFERROR(INDEX(Products!$F$5:$F$54,MATCH($C29,Products!$A$5:$A$54,0)),0)) | V29: =IF($A29="","",$M29-$T29-$S29-$U29-$G29) | W29: =IF($A29="","",IF($M29-$T29>0,$V29/($M29-$T29),"")) | X29: =IF($A29="","",DATE(YEAR($A29),MONTH($A29),1))
A30: 46304 | B30: Etsy | C30: Soy Candle 8oz | D30: 1 | E30: 24 | F30: 6 | G30: 6.5 | I30: N | J30: N | M30: =IF($A30="","",IF($D30="",1,$D30)*$E30+$F30-$H30) | N30: =IF($A30="","",IF($B30="Etsy",IF($D30="",1,$D30)*Settings!$C$19,0)) | O30: =IF($A30="","",IF($B30="Etsy",Settings!$C$20*($M30+IF(Settings!$C$54="Y",0,$H30)),0)) | P30: =IF($A30="","",IF($B30="Etsy",Settings!$C$21*$M30*(1+Settings!$C$55)+Settings!$C$22,IF($B30="Shopify",Settings!$C$14*$M30+Settings!$C$15,0))) | Q30: =IF($A30="","",IF(AND($B30="Etsy",$I30="Y"),MIN(Settings!$C$12*($M30+IF(Settings!$C$54="Y",0,$H30)),Settings!$C$25),0)) | R30: =IF($A30="","",IF(AND($B30="Etsy",$J30="Y",$L30="Y",$M30>0),($O30+Settings!$C$21*$M30*(1+Settings!$C$55)+IF(Settings!$C$59="Y",$Q30,0))*$T30/$M30+IF(AND(Settings!$C$58="Y",$T30>=$M30),Settings!$C$22,0),0)) | S30: =IF($A30="","",$N30+$O30+$P30+$Q30-$R30) | T30: =IF($A30="","",IF($J30="Y",IF($K30="",$M30,MIN($K30,$M30)),0)) | U30: =IF($A30="","",IF($D30="",1,$D30)*IFERROR(INDEX(Products!$F$5:$F$54,MATCH($C30,Products!$A$5:$A$54,0)),0)) | V30: =IF($A30="","",$M30-$T30-$S30-$U30-$G30) | W30: =IF($A30="","",IF($M30-$T30>0,$V30/($M30-$T30),"")) | X30: =IF($A30="","",DATE(YEAR($A30),MONTH($A30),1))
A31: 46306 | B31: Etsy | C31: Ceramic Mug | D31: 1 | E31: 32 | F31: 6.95 | G31: 7.2 | I31: N | J31: Y | K31: 5 | L31: N | M31: =IF($A31="","",IF($D31="",1,$D31)*$E31+$F31-$H31) | N31: =IF($A31="","",IF($B31="Etsy",IF($D31="",1,$D31)*Settings!$C$19,0)) | O31: =IF($A31="","",IF($B31="Etsy",Settings!$C$20*($M31+IF(Settings!$C$54="Y",0,$H31)),0)) | P31: =IF($A31="","",IF($B31="Etsy",Settings!$C$21*$M31*(1+Settings!$C$55)+Settings!$C$22,IF($B31="Shopify",Settings!$C$14*$M31+Settings!$C$15,0))) | Q31: =IF($A31="","",IF(AND($B31="Etsy",$I31="Y"),MIN(Settings!$C$12*($M31+IF(Settings!$C$54="Y",0,$H31)),Settings!$C$25),0)) | R31: =IF($A31="","",IF(AND($B31="Etsy",$J31="Y",$L31="Y",$M31>0),($O31+Settings!$C$21*$M31*(1+Settings!$C$55)+IF(Settings!$C$59="Y",$Q31,0))*$T31/$M31+IF(AND(Settings!$C$58="Y",$T31>=$M31),Settings!$C$22,0),0)) | S31: =IF($A31="","",$N31+$O31+$P31+$Q31-$R31) | T31: =IF($A31="","",IF($J31="Y",IF($K31="",$M31,MIN($K31,$M31)),0)) | U31: =IF($A31="","",IF($D31="",1,$D31)*IFERROR(INDEX(Products!$F$5:$F$54,MATCH($C31,Products!$A$5:$A$54,0)),0)) | V31: =IF($A31="","",$M31-$T31-$S31-$U31-$G31) | W31: =IF($A31="","",IF($M31-$T31>0,$V31/($M31-$T31),"")) | X31: =IF($A31="","",DATE(YEAR($A31),MONTH($A31),1))
A32: 46308 | B32: Etsy | C32: Beaded Bracelet | D32: 1 | E32: 18 | F32: 0 | G32: 4 | I32: Y | J32: N | M32: =IF($A32="","",IF($D32="",1,$D32)*$E32+$F32-$H32) | N32: =IF($A32="","",IF($B32="Etsy",IF($D32="",1,$D32)*Settings!$C$19,0)) | O32: =IF($A32="","",IF($B32="Etsy",Settings!$C$20*($M32+IF(Settings!$C$54="Y",0,$H32)),0)) | P32: =IF($A32="","",IF($B32="Etsy",Settings!$C$21*$M32*(1+Settings!$C$55)+Settings!$C$22,IF($B32="Shopify",Settings!$C$14*$M32+Settings!$C$15,0))) | Q32: =IF($A32="","",IF(AND($B32="Etsy",$I32="Y"),MIN(Settings!$C$12*($M32+IF(Settings!$C$54="Y",0,$H32)),Settings!$C$25),0)) | R32: =IF($A32="","",IF(AND($B32="Etsy",$J32="Y",$L32="Y",$M32>0),($O32+Settings!$C$21*$M32*(1+Settings!$C$55)+IF(Settings!$C$59="Y",$Q32,0))*$T32/$M32+IF(AND(Settings!$C$58="Y",$T32>=$M32),Settings!$C$22,0),0)) | S32: =IF($A32="","",$N32+$O32+$P32+$Q32-$R32) | T32: =IF($A32="","",IF($J32="Y",IF($K32="",$M32,MIN($K32,$M32)),0)) | U32: =IF($A32="","",IF($D32="",1,$D32)*IFERROR(INDEX(Products!$F$5:$F$54,MATCH($C32,Products!$A$5:$A$54,0)),0)) | V32: =IF($A32="","",$M32-$T32-$S32-$U32-$G32) | W32: =IF($A32="","",IF($M32-$T32>0,$V32/($M32-$T32),"")) | X32: =IF($A32="","",DATE(YEAR($A32),MONTH($A32),1))
A33: 46310 | B33: Shopify | C33: Linen Tote Bag | D33: 1 | E33: 28 | F33: 5.5 | G33: 5 | I33: N | J33: N | M33: =IF($A33="","",IF($D33="",1,$D33)*$E33+$F33-$H33) | N33: =IF($A33="","",IF($B33="Etsy",IF($D33="",1,$D33)*Settings!$C$19,0)) | O33: =IF($A33="","",IF($B33="Etsy",Settings!$C$20*($M33+IF(Settings!$C$54="Y",0,$H33)),0)) | P33: =IF($A33="","",IF($B33="Etsy",Settings!$C$21*$M33*(1+Settings!$C$55)+Settings!$C$22,IF($B33="Shopify",Settings!$C$14*$M33+Settings!$C$15,0))) | Q33: =IF($A33="","",IF(AND($B33="Etsy",$I33="Y"),MIN(Settings!$C$12*($M33+IF(Settings!$C$54="Y",0,$H33)),Settings!$C$25),0)) | R33: =IF($A33="","",IF(AND($B33="Etsy",$J33="Y",$L33="Y",$M33>0),($O33+Settings!$C$21*$M33*(1+Settings!$C$55)+IF(Settings!$C$59="Y",$Q33,0))*$T33/$M33+IF(AND(Settings!$C$58="Y",$T33>=$M33),Settings!$C$22,0),0)) | S33: =IF($A33="","",$N33+$O33+$P33+$Q33-$R33) | T33: =IF($A33="","",IF($J33="Y",IF($K33="",$M33,MIN($K33,$M33)),0)) | U33: =IF($A33="","",IF($D33="",1,$D33)*IFERROR(INDEX(Products!$F$5:$F$54,MATCH($C33,Products!$A$5:$A$54,0)),0)) | V33: =IF($A33="","",$M33-$T33-$S33-$U33-$G33) | W33: =IF($A33="","",IF($M33-$T33>0,$V33/($M33-$T33),"")) | X33: =IF($A33="","",DATE(YEAR($A33),MONTH($A33),1))
A34: 46312 | B34: Etsy | C34: Art Print A4 | D34: 2 | E34: 15 | F34: 0 | G34: 1.8 | I34: N | J34: N | M34: =IF($A34="","",IF($D34="",1,$D34)*$E34+$F34-$H34) | N34: =IF($A34="","",IF($B34="Etsy",IF($D34="",1,$D34)*Settings!$C$19,0)) | O34: =IF($A34="","",IF($B34="Etsy",Settings!$C$20*($M34+IF(Settings!$C$54="Y",0,$H34)),0)) | P34: =IF($A34="","",IF($B34="Etsy",Settings!$C$21*$M34*(1+Settings!$C$55)+Settings!$C$22,IF($B34="Shopify",Settings!$C$14*$M34+Settings!$C$15,0))) | Q34: =IF($A34="","",IF(AND($B34="Etsy",$I34="Y"),MIN(Settings!$C$12*($M34+IF(Settings!$C$54="Y",0,$H34)),Settings!$C$25),0)) | R34: =IF($A34="","",IF(AND($B34="Etsy",$J34="Y",$L34="Y",$M34>0),($O34+Settings!$C$21*$M34*(1+Settings!$C$55)+IF(Settings!$C$59="Y",$Q34,0))*$T34/$M34+IF(AND(Settings!$C$58="Y",$T34>=$M34),Settings!$C$22,0),0)) | S34: =IF($A34="","",$N34+$O34+$P34+$Q34-$R34) | T34: =IF($A34="","",IF($J34="Y",IF($K34="",$M34,MIN($K34,$M34)),0)) | U34: =IF($A34="","",IF($D34="",1,$D34)*IFERROR(INDEX(Products!$F$5:$F$54,MATCH($C34,Products!$A$5:$A$54,0)),0)) | V34: =IF($A34="","",$M34-$T34-$S34-$U34-$G34) | W34: =IF($A34="","",IF($M34-$T34>0,$V34/($M34-$T34),"")) | X34: =IF($A34="","",DATE(YEAR($A34),MONTH($A34),1))
A35: 46314 | B35: Etsy | C35: Soy Candle 8oz | D35: 1 | E35: 24 | F35: 6 | G35: 6.5 | I35: N | J35: N | M35: =IF($A35="","",IF($D35="",1,$D35)*$E35+$F35-$H35) | N35: =IF($A35="","",IF($B35="Etsy",IF($D35="",1,$D35)*Settings!$C$19,0)) | O35: =IF($A35="","",IF($B35="Etsy",Settings!$C$20*($M35+IF(Settings!$C$54="Y",0,$H35)),0)) | P35: =IF($A35="","",IF($B35="Etsy",Settings!$C$21*$M35*(1+Settings!$C$55)+Settings!$C$22,IF($B35="Shopify",Settings!$C$14*$M35+Settings!$C$15,0))) | Q35: =IF($A35="","",IF(AND($B35="Etsy",$I35="Y"),MIN(Settings!$C$12*($M35+IF(Settings!$C$54="Y",0,$H35)),Settings!$C$25),0)) | R35: =IF($A35="","",IF(AND($B35="Etsy",$J35="Y",$L35="Y",$M35>0),($O35+Settings!$C$21*$M35*(1+Settings!$C$55)+IF(Settings!$C$59="Y",$Q35,0))*$T35/$M35+IF(AND(Settings!$C$58="Y",$T35>=$M35),Settings!$C$22,0),0)) | S35: =IF($A35="","",$N35+$O35+$P35+$Q35-$R35) | T35: =IF($A35="","",IF($J35="Y",IF($K35="",$M35,MIN($K35,$M35)),0)) | U35: =IF($A35="","",IF($D35="",1,$D35)*IFERROR(INDEX(Products!$F$5:$F$54,MATCH($C35,Products!$A$5:$A$54,0)),0)) | V35: =IF($A35="","",$M35-$T35-$S35-$U35-$G35) | W35: =IF($A35="","",IF($M35-$T35>0,$V35/($M35-$T35),"")) | X35: =IF($A35="","",DATE(YEAR($A35),MONTH($A35),1))
M36: =IF($A36="","",IF($D36="",1,$D36)*$E36+$F36-$H36) | N36: =IF($A36="","",IF($B36="Etsy",IF($D36="",1,$D36)*Settings!$C$19,0)) | O36: =IF($A36="","",IF($B36="Etsy",Settings!$C$20*($M36+IF(Settings!$C$54="Y",0,$H36)),0)) | P36: =IF($A36="","",IF($B36="Etsy",Settings!$C$21*$M36*(1+Settings!$C$55)+Settings!$C$22,IF($B36="Shopify",Settings!$C$14*$M36+Settings!$C$15,0))) | Q36: =IF($A36="","",IF(AND($B36="Etsy",$I36="Y"),MIN(Settings!$C$12*($M36+IF(Settings!$C$54="Y",0,$H36)),Settings!$C$25),0)) | R36: =IF($A36="","",IF(AND($B36="Etsy",$J36="Y",$L36="Y",$M36>0),($O36+Settings!$C$21*$M36*(1+Settings!$C$55)+IF(Settings!$C$59="Y",$Q36,0))*$T36/$M36+IF(AND(Settings!$C$58="Y",$T36>=$M36),Settings!$C$22,0),0)) | S36: =IF($A36="","",$N36+$O36+$P36+$Q36-$R36) | T36: =IF($A36="","",IF($J36="Y",IF($K36="",$M36,MIN($K36,$M36)),0)) | U36: =IF($A36="","",IF($D36="",1,$D36)*IFERROR(INDEX(Products!$F$5:$F$54,MATCH($C36,Products!$A$5:$A$54,0)),0)) | V36: =IF($A36="","",$M36-$T36-$S36-$U36-$G36) | W36: =IF($A36="","",IF($M36-$T36>0,$V36/($M36-$T36),"")) | X36: =IF($A36="","",DATE(YEAR($A36),MONTH($A36),1))
